<mujoco model="KGF65-KA_BeltConveyor">
  <compiler angle="degree" meshdir="." texturedir="."/>
  <option gravity="0 0 -9.81"
          timestep="0.002"
          solver="Newton"
          iterations="100"
          tolerance="1e-10"
          cone="pyramidal"
          impratio="10"/>
          
  <!--  ASSET-->
  <asset>
    <mesh name="simlify" file="simlify.stl" scale="0.001 0.001 0.001"/>
    <texture name="belt_tex"  type="2d" file="belt_stripe.png"/>
    <texture name="metal_tex" type="2d" builtin="flat"
             rgb1=".48 .50 .52" width="1" height="1"/>
    <texture name="drum_tex"  type="2d" builtin="checker"
             rgb1=".18 .18 .20" rgb2=".28 .28 .32" width="64" height="64"/>
    <texture name="grid_tex"  type="2d" builtin="checker"
             rgb1=".20 .20 .20" rgb2=".26 .26 .26" width="64" height="64"/>
    <material name="belt_mat"    texture="belt_tex"
              texrepeat="20 1"   specular="0.05" shininess="0.03"
              rgba="0.12 0.48 0.16 1"/>
    <material name="frame_mat"   texture="metal_tex"
              specular="0.4"    shininess="0.25"
              rgba=".48 .50 .52 1"/>
    <material name="drum_mat"    texture="drum_tex"
              texrepeat="8 4"   specular="0.7" shininess="0.6"
              rgba="1 1 1 1"/>
    <material name="ground_mat"  texture="grid_tex"
              texrepeat="24 24" specular="0.05" shininess="0.03"
              rgba="1 1 1 1"/>
    <!-- Object materials -->
    <material name="obj0_mat" rgba="1 0 0 1"/>
    <material name="obj1_mat" rgba="0 0 1 1"/>
    <material name="obj2_mat" rgba="1 1 0 1"/>
    <material name="obj3_mat" rgba="1 0 0 1"/>
    <material name="obj4_mat" rgba="0 0 1 1"/>
    <material name="obj5_mat" rgba="1 1 0 1"/>
    <material name="obj6_mat" rgba="1 0 0 1"/>
    <material name="obj7_mat" rgba="0 0 1 1"/>
    <material name="obj8_mat" rgba="1 1 0 1"/>
    <material name="obj9_mat" rgba="1 0 0 1"/>
  </asset>

  <!-- DEFAULT -->
  <default>
    <geom condim="4"
          friction="0.8 0.008 0.0005"
          solimp="0.98 0.999 0.001 0.5 2"
          solref="0.010 1"/>
    <joint limited="false" damping="0.02" armature="0.001"/>

    <!-- Conveyor objects -->
    <default class="flat_obj">
      <geom type="box"
            size="0.030 0.030 0.030"
            condim="4"
            friction="0.75 0.006 0.0004"
            solimp="0.97 0.999 0.002 0.5 2"
            solref="0.010 1"
            density="600"
            contype="1" conaffinity="1"/>
      <joint type="free" damping="0.0" armature="0.0"/>
    </default>

    <!-- Bin walls -->
    <default class="bin_wall">
      <geom type="box"
            condim="3"
            friction="0.4 0.004 0.0002"
            solimp="0.98 0.999 0.001 0.5 2"
            solref="0.010 1"
            contype="1" conaffinity="1"/>
    </default>

    <!-- Pusher face -->
    <default class="pusher_face">
      <geom type="box"
            condim="3"
            friction="0.3 0.003 0.0001"
            solimp="0.99 0.999 0.001 0.5 2"
            solref="0.008 1"
            contype="1" conaffinity="1"/>
    </default>

  </default>

  <!-- WORLDBODY -->
  <worldbody>
    <!-- Ground plane -->
    <geom name="ground" type="plane" size="12 8 0.1"
          material="ground_mat"
          friction="0.5 0.005 0.0002"
          solimp="0.99 0.999 0.001" solref="0.010 1"
          contype="1" conaffinity="1"/>
    <!-- Lighting -->
    <light name="sun"  directional="true"
           diffuse=".85 .85 .85" specular=".2 .2 .2"
           pos="2 -2 6" dir="-.3 .4 -1" castshadow="true"/>
    <light name="fill" directional="false" diffuse=".35 .35 .38"
           pos="-1 3 4" dir=".4 -.5 -1" castshadow="false"/>
    <light name="top"  directional="false" diffuse=".25 .25 .25"
           pos="1 0 5"  dir="0 0 -1"     castshadow="false"/>
    <!-- SIDE CAMERA MOUNT -->

    <!-- Vertical post -->
    <geom type="cylinder" size="0.014 0.350"
          pos="0.40 -0.19 0.350"
          rgba=".30 .30 .30 1" contype="0" conaffinity="0"/>

    <!-- Camera body -->
    <body name="camera_body" pos="0.40 -0.19 0.70" euler="47 0 0">
      <!-- Housing box -->
      <geom type="box" size="0.028 0.022 0.042"
            rgba=".10 .10 .10 1" contype="0" conaffinity="0"/>
      <!-- Lens barrel -->
      <geom type="cylinder" size="0.014 0.016" pos="0 0 -0.056"
            rgba=".07 .07 .07 1" contype="0" conaffinity="0"/>
      <!-- Lens glass -->
      <geom type="cylinder" size="0.011 0.003" pos="0 0 -0.075"
            rgba=".25 .45 .90 0.75" contype="0" conaffinity="0"/>
      <!-- Status LED -->
      <geom type="sphere" size="0.005" pos="0 0.024 0.030"
            rgba=".05 .90 .15 1" contype="0" conaffinity="0"/>
      <!-- Camera sensor -->
      <camera name="side_camera" fovy="50"/>
    </body>

    <!--  CONVEYOR FRAME ASSEMBLY  -->
    <body name="conveyor_frame" pos="0 0 0">
      <geom name="frame_mesh" type="mesh" mesh="simlify"
            euler="0 90 90"
            pos="0.875 0 0.440"
            contype="0" conaffinity="0"
            material="frame_mat"/>
      <!-- Leg pairs -->
      <geom type="box" size=".018 .018 .237" pos=".10  -.110 .237" material="frame_mat" contype="0" conaffinity="0"/>
      <geom type="box" size=".018 .018 .237" pos=".10   .110 .237" material="frame_mat" contype="0" conaffinity="0"/>
      <geom type="box" size=".018 .018 .237" pos="1.00 -.110 .237" material="frame_mat" contype="0" conaffinity="0"/>
      <geom type="box" size=".018 .018 .237" pos="1.00  .110 .237" material="frame_mat" contype="0" conaffinity="0"/>
      <geom type="box" size=".018 .018 .237" pos="1.90 -.110 .237" material="frame_mat" contype="0" conaffinity="0"/>
      <geom type="box" size=".018 .018 .237" pos="1.90  .110 .237" material="frame_mat" contype="0" conaffinity="0"/>
      <!-- Rails & bed -->
      <geom name="rail_l" type="box" size="1.0 .012 .022" pos="1.0 -.138 .474" material="frame_mat" contype="0" conaffinity="0"/>
      <geom name="rail_r" type="box" size="1.0 .012 .022" pos="1.0  .138 .474" material="frame_mat" contype="0" conaffinity="0"/>
      <geom name="bed"    type="box" size="1.0 .122 .005" pos="1.0  .000 .487" material="frame_mat" contype="0" conaffinity="0"/>
      <!-- Drive drum -->
      <geom type="cylinder" size=".026 .126" pos="0.0  0.000 0.500" euler="90 0 0" material="drum_mat"  contype="0" conaffinity="0"/>
      <geom type="cylinder" size=".031 .006" pos="0.0  .133 0.500" euler="90 0 0"  material="frame_mat" contype="0" conaffinity="0"/>
      <geom type="cylinder" size=".031 .006" pos="0.0 -.133 0.500" euler="90 0 0"  material="frame_mat" contype="0" conaffinity="0"/>
      <geom type="cylinder" size=".010 .028" pos="0.0  .165 0.500" euler="90 0 0"  material="frame_mat" contype="0" conaffinity="0"/>
      <geom type="cylinder" size=".010 .028" pos="0.0 -.165 0.500" euler="90 0 0"  material="frame_mat" contype="0" conaffinity="0"/>
      <!-- Passive drum -->
      <geom type="cylinder" size=".026 .126" pos="2.0  0.000 0.500" euler="90 0 0" material="drum_mat"  contype="0" conaffinity="0"/>
      <geom type="cylinder" size=".031 .006" pos="2.0  .133 0.500" euler="90 0 0"  material="frame_mat" contype="0" conaffinity="0"/>
      <geom type="cylinder" size=".031 .006" pos="2.0 -.133 0.500" euler="90 0 0"  material="frame_mat" contype="0" conaffinity="0"/>
      <geom type="cylinder" size=".010 .028" pos="2.0  .165 0.500" euler="90 0 0"  material="frame_mat" contype="0" conaffinity="0"/>
      <geom type="cylinder" size=".010 .028" pos="2.0 -.165 0.500" euler="90 0 0"  material="frame_mat" contype="0" conaffinity="0"/>
      <!-- Belt visual -->
      <geom name="belt_visual" type="box" size="1.0 0.122 0.002"
            pos="1.0 0 0.524"
            contype="0" conaffinity="0"
            material="belt_mat"/>
      <!-- Belt physics floor -->
      <geom name="belt_floor" type="box"
            size="1.0 0.125 0.002"
            pos="1.0 0 0.524"
            condim="4"
            friction="1.4 0.008 0.0006"
            solimp="0.97 0.999 0.002 0.5 2"
            solref="0.010 1"
            contype="1" conaffinity="1"
            rgba="0 0 0 0"/>
    </body><!-- conveyor_frame -->

    <!--  DROP-OFF BINS  -->
    <!-- RED BIN  -->
    <body name="red_bin" pos="0.8 -0.5 0">
      <geom class="bin_wall" size=".255 .148 .010" pos="0 0 .010"    rgba=".85 .08 .08 1"/>
      <geom class="bin_wall" size=".012 .148 .090" pos="-.255 0 .100" rgba=".85 .08 .08 1"/>
      <geom class="bin_wall" size=".255 .012 .090" pos="0 -.148 .100" rgba=".85 .08 .08 1"/>
      <geom class="bin_wall" size=".255 .012 .090" pos="0  .148 .100" rgba=".85 .08 .08 1"/>
      <geom class="bin_wall" size=".012 .148 .045" pos=".255 0 .055"  rgba=".85 .08 .08 1"/>
    </body>
    <!-- BLUE BIN  -->
    <body name="blue_bin" pos="2.25 0.00 0">
      <geom class="bin_wall" size=".255 .148 .010" pos="0 0 .010"    rgba=".08 .18 .82 1"/>
      <geom class="bin_wall" size=".012 .148 .090" pos="-.255 0 .100" rgba=".08 .18 .82 1"/>
      <geom class="bin_wall" size=".255 .012 .090" pos="0 -.148 .100" rgba=".08 .18 .82 1"/>
      <geom class="bin_wall" size=".255 .012 .090" pos="0  .148 .100" rgba=".08 .18 .82 1"/>
      <geom class="bin_wall" size=".012 .148 .045" pos=".255 0 .055"  rgba=".08 .18 .82 1"/>
    </body>
    <!-- YELLOW BIN  -->
    <body name="yellow_bin" pos="1.5 -0.5 0">
      <geom class="bin_wall" size=".255 .148 .010" pos="0 0 .010"    rgba=".92 .80 .00 1"/>
      <geom class="bin_wall" size=".012 .148 .090" pos="-.255 0 .100" rgba=".92 .80 .00 1"/>
      <geom class="bin_wall" size=".255 .012 .090" pos="0 -.148 .100" rgba=".92 .80 .00 1"/>
      <geom class="bin_wall" size=".255 .012 .090" pos="0  .148 .100" rgba=".92 .80 .00 1"/>
      <geom class="bin_wall" size=".012 .148 .045" pos=".255 0 .055"  rgba=".92 .80 .00 1"/>
    </body>

    <!-- PUSHER RED PEDESTAL -->
    <!-- Vertical post -->
    <geom type="cylinder" size="0.014 0.300"
          pos="0.80 0.38 0.300"
          rgba=".30 .30 .30 1" contype="0" conaffinity="0"/>
    <!-- Base plate -->
    <geom type="box" size="0.040 0.040 0.008"
          pos="0.80 0.38 0.008"
          rgba=".25 .25 .25 1" contype="0" conaffinity="0"/>

    <!-- PUSHER YELLOW PEDESTAL -->
    <!-- Vertical post -->
    <geom type="cylinder" size="0.014 0.300"
          pos="1.480 0.38 0.300"
          rgba=".30 .30 .30 1" contype="0" conaffinity="0"/>
    <!-- Base plate -->
    <geom type="box" size="0.040 0.040 0.008"
          pos="1.480 0.38 0.008"
          rgba=".25 .25 .25 1" contype="0" conaffinity="0"/>

    <!--  PUSHER 1  —  RED objects  -->
    <body name="pusher_red" pos="0.80 0.20 0.6">
      <!-- Slide joint -->
      <joint name="pusher_red_slide" type="slide" axis="0 1 0"
             limited="true" range="-0.45 0.0"
             damping="80" armature="0.02"/>
      <!-- Pusher face -->
      <geom class="pusher_face"
            name="pusher_red_face"
            size="0.080 0.010 0.055"
            rgba="0.90 0.10 0.10 1.0"/>
      <!-- Visual arm -->
      <geom type="box" size="0.006 0.315 0.006" pos="0 0.315 0"
            rgba="0.50 0.50 0.50 1" contype="0" conaffinity="0"/>
      <!-- Visual wall bracket -->
      <geom type="box" size="0.020 0.006 0.040" pos="0 0.630 0"
            rgba="0.40 0.40 0.40 1" contype="0" conaffinity="0"/>
    </body><!-- pusher_red -->

    <!--   PUSHER 2  —  YELLOW objects  -->
    <body name="pusher_yellow" pos="1.480 0.20 0.6">
      <joint name="pusher_yellow_slide" type="slide" axis="0 1 0"
             limited="true" range="-0.45 0.0"
             damping="80" armature="0.02"/>
      <geom class="pusher_face"
            name="pusher_yellow_face"
            size="0.080 0.010 0.055"
            rgba="0.95 0.82 0.05 1.0"/>
      <geom type="box" size="0.006 0.315 0.006" pos="0 0.315 0"
            rgba="0.50 0.50 0.50 1" contype="0" conaffinity="0"/>
      <geom type="box" size="0.020 0.006 0.040" pos="0 0.630 0"
            rgba="0.40 0.40 0.40 1" contype="0" conaffinity="0"/>
    </body><!-- pusher_yellow -->

    <!-- 10 OBJECTS-->
    <!-- Red bin -->
    <body name="object_0" pos="0.7625 -0.4375 0.050">
      <joint name="obj0_free" type="free" damping="0" armature="0"/>
      <geom class="flat_obj" material="obj0_mat"/>
    </body>
    <body name="object_3" pos="0.8375 -0.4375 0.050">
      <joint name="obj3_free" type="free" damping="0" armature="0"/>
      <geom class="flat_obj" material="obj3_mat"/>
    </body>
    <body name="object_6" pos="0.7625 -0.3625 0.050">
      <joint name="obj6_free" type="free" damping="0" armature="0"/>
      <geom class="flat_obj" material="obj6_mat"/>
    </body>
    <body name="object_9" pos="0.8375 -0.3625 0.050">
      <joint name="obj9_free" type="free" damping="0" armature="0"/>
      <geom class="flat_obj" material="obj9_mat"/>
    </body>

    <!-- Blue bin -->
    <body name="object_1" pos="2.25 -0.075 0.050">
      <joint name="obj1_free" type="free" damping="0" armature="0"/>
      <geom class="flat_obj" material="obj1_mat"/>
    </body>
    <body name="object_4" pos="2.25  0.000 0.050">
      <joint name="obj4_free" type="free" damping="0" armature="0"/>
      <geom class="flat_obj" material="obj4_mat"/>
    </body>
    <body name="object_7" pos="2.25  0.075 0.050">
      <joint name="obj7_free" type="free" damping="0" armature="0"/>
      <geom class="flat_obj" material="obj7_mat"/>
    </body>

    <!-- Yellow bin -->
    <body name="object_2" pos="1.425 -0.4 0.050">
      <joint name="obj2_free" type="free" damping="0" armature="0"/>
      <geom class="flat_obj" material="obj2_mat"/>
    </body>
    <body name="object_5" pos="1.500 -0.4 0.050">
      <joint name="obj5_free" type="free" damping="0" armature="0"/>
      <geom class="flat_obj" material="obj5_mat"/>
    </body>
    <body name="object_8" pos="1.575 -0.4 0.050">
      <joint name="obj8_free" type="free" damping="0" armature="0"/>
      <geom class="flat_obj" material="obj8_mat"/>
    </body>

  </worldbody>

  <!--  ACTUATORS -->
  <actuator>
    <!-- Pusher  -->
    <position name="act_push_red"
              joint="pusher_red_slide"
              kp="3000"
              ctrllimited="true"  ctrlrange="-0.45 0.0"
              forcelimited="true" forcerange="-1000 1000"/>
    <!-- Pusher 2 -->
    <position name="act_push_yellow"
              joint="pusher_yellow_slide"
              kp="3000"
              ctrllimited="true"  ctrlrange="-0.45 0.0"
              forcelimited="true" forcerange="-1000 1000"/>
  </actuator>
</mujoco>